Exception in thread Thread-1:
Traceback (most recent call last):
  File "/home/user/miniconda3/envs/energy/lib/python3.9/site-packages/urllib3/connection.py", line 169, in _new_conn
    conn = connection.create_connection(
  File "/home/user/miniconda3/envs/energy/lib/python3.9/site-packages/urllib3/util/connection.py", line 96, in create_connection
    raise err
  File "/home/user/miniconda3/envs/energy/lib/python3.9/site-packages/urllib3/util/connection.py", line 86, in create_connection
    sock.connect(sa)
ConnectionRefusedError: [Errno 111] Connection refused

During handling of the above exception, another exception occurred:

Traceback (most recent call last):
  File "/home/user/miniconda3/envs/energy/lib/python3.9/site-packages/urllib3/connectionpool.py", line 699, in urlopen
    httplib_response = self._make_request(
  File "/home/user/miniconda3/envs/energy/lib/python3.9/site-packages/urllib3/connectionpool.py", line 394, in _make_request
    conn.request(method, url, **httplib_request_kw)
  File "/home/user/miniconda3/envs/energy/lib/python3.9/site-packages/urllib3/connection.py", line 234, in request
    super(HTTPConnection, self).request(method, url, body=body, headers=headers)
  File "/home/user/miniconda3/envs/energy/lib/python3.9/http/client.py", line 1255, in request
    self._send_request(method, url, body, headers, encode_chunked)
  File "/home/user/miniconda3/envs/energy/lib/python3.9/http/client.py", line 1301, in _send_request
    self.endheaders(body, encode_chunked=encode_chunked)
  File "/home/user/miniconda3/envs/energy/lib/python3.9/http/client.py", line 1250, in endheaders
    self._send_output(message_body, encode_chunked=encode_chunked)
  File "/home/user/miniconda3/envs/energy/lib/python3.9/http/client.py", line 1010, in _send_output
    self.send(msg)
  File "/home/user/miniconda3/envs/energy/lib/python3.9/http/client.py", line 950, in send
    self.connect()
  File "/home/user/miniconda3/envs/energy/lib/python3.9/site-packages/urllib3/connection.py", line 200, in connect
    conn = self._new_conn()
  File "/home/user/miniconda3/envs/energy/lib/python3.9/site-packages/urllib3/connection.py", line 181, in _new_conn
    raise NewConnectionError(
urllib3.exceptions.NewConnectionError: <urllib3.connection.HTTPConnection object at 0x7fcd9ba59730>: Failed to establish a new connection: [Errno 111] Connection refused

During handling of the above exception, another exception occurred:

Traceback (most recent call last):
  File "/home/user/miniconda3/envs/energy/lib/python3.9/site-packages/requests/adapters.py", line 439, in send
    resp = conn.urlopen(
  File "/home/user/miniconda3/envs/energy/lib/python3.9/site-packages/urllib3/connectionpool.py", line 755, in urlopen
    retries = retries.increment(
  File "/home/user/miniconda3/envs/energy/lib/python3.9/site-packages/urllib3/util/retry.py", line 573, in increment
    raise MaxRetryError(_pool, url, error or ResponseError(cause))
urllib3.exceptions.MaxRetryError: HTTPConnectionPool(host='127.0.0.1', port=6002): Max retries exceeded with url: /api/extx (Caused by NewConnectionError('<urllib3.connection.HTTPConnection object at 0x7fcd9ba59730>: Failed to establish a new connection: [Errno 111] Connection refused'))

During handling of the above exception, another exception occurred:

Traceback (most recent call last):
  File "/home/user/miniconda3/envs/energy/lib/python3.9/threading.py", line 954, in _bootstrap_inner
    self.run()
  File "/home/user/miniconda3/envs/energy/lib/python3.9/threading.py", line 892, in run
    self._target(*self._args, **self._kwargs)
  File "/home/user/miniconda3/envs/energy/lib/python3.9/site-packages/requests/api.py", line 119, in post
    return request('post', url, data=data, json=json, **kwargs)
  File "/home/user/miniconda3/envs/energy/lib/python3.9/site-packages/requests/api.py", line 61, in request
    return session.request(method=method, url=url, **kwargs)
  File "/home/user/miniconda3/envs/energy/lib/python3.9/site-packages/requests/sessions.py", line 542, in request
    resp = self.send(prep, **send_kwargs)
  File "/home/user/miniconda3/envs/energy/lib/python3.9/site-packages/requests/sessions.py", line 655, in send
    r = adapter.send(request, **kwargs)
  File "/home/user/miniconda3/envs/energy/lib/python3.9/site-packages/requests/adapters.py", line 516, in send
    raise ConnectionError(e, request=request)
requests.exceptions.ConnectionError: HTTPConnectionPool(host='127.0.0.1', port=6002): Max retries exceeded with url: /api/extx (Caused by NewConnectionError('<urllib3.connection.HTTPConnection object at 0x7fcd9ba59730>: Failed to establish a new connection: [Errno 111] Connection refused'))
